Workbook

Sheet Disclaimer
B2: Disclaimer
B4: ="This Investor Presentation is provided for informational purposes only and does not constitute an offer to buy or a solicitation of an offer to invest, or to procure an investment in "&'Get Started'!D9&" (the “Company”)." -> This Investor Presentation is provided for informational purposes only and does not constitute an offer to buy or a solicitation of an offer to invest, or to procure an investment in 46387 (the “Company”).
B5: Investments in the Company, if offered, will only be offered to a selected number of accredited investors, and only on the basis of a private offering memorandum for the Company. There are significant risks that are not presented and disclosed in this Investor Presentation. These risks could have a significant negative impact on the performance of the Company.
B6: This Investor Presentation contains forward-looking statements regarding our business plans and prospects and financial conditions, all statements, other than statements of historical fact, in this Investor Presentation, and the attached exhibits, including, among other things, statements regarding our competitive strengths, business strategy, financial projections and plans and objectives of management are forward-looking statements. Although we believe that the expectations reflected in such forward-looking statements are reasonable, there can be no assurance that such expectations will prove to be correct. Forward-looking statements are inherently subject to risks and uncertainties, many of which cannot be predicted with accuracy and some of which might not even be anticipated. Future events and actual results, financial or otherwise, could differ materially from those set forth in, or contemplated by, the forward-looking statements in this Investor Presentation, and, as such, the forward-looking statements contained herein should not be relied upon when making your investment decision. We undertake no obligation to update or revise any forward-looking statements.
B7: The financial projections in this Investor Presentation present, to the best of management’s knowledge and belief, the Company’s expected financial position, results of operations, and cash flows for the forecast period. Accordingly, the financial projections reflect its judgment, as of the date of these financial projections, of the expected conditions and its expected course of action following the sale of securities by the Company. The assumptions disclosed herein are those that management believes are significant to the financial projections. There will usually be differences between the projected and actual results, because events and circumstances frequently do not occur as expected, and those differences may be material. Since the projections are based upon assumptions about circumstances and events that have not yet taken place regarding costs, income, expenses and federal tax matters, which are subject to variations and economic events as future operations actually occur, they do not necessarily reflect the results that will be achieved and should not be relied upon. In all cases, the targeted returns are not predictions or projections that the results in the pro forma financials will be achieved nor of the performance of any investment, and are expressly subject to all assumptions embedded in the pro forma financials and the risk factors disclosed herein. This investment has a high degree of risk, and there can be no assurances that all or any of the assumptions will be true or that an investment’s actual performance will bear any relation to these hypothetical illustrations.
B8: This information contained in this Investor Presentation includes proprietary information, is strictly confidential, and is not to be used or distributed to others without the express written consent of the Company.
B9: This document has been prepared solely for information purposes and is being furnished solely for use by prospective purchasers in considering their interest in obtaining additional information and making their own evaluation of the Company and does not contain all of the information that a prospective purchaser may desire. This information reflects various assumptions by the Company concerning anticipated results, which assumptions may or may not prove to be correct, and the Company has no obligation to update such information. The only information that will have any legal effect will be that specifically contained in definitive documentation. This Investor Presentation has been submitted confidentially to a limited number of investors so that they can consider their interest in obtaining additional information and making their own evaluation of the Company. No offers to purchase the securities of the Company will be accepted prior to (1) the receipt by recipient of a complete private offering memorandum and (2) determination by the Company that the recipient is an appropriate purchaser in light of standards contained in U.S. Securities laws after a full evaluation of recipient by the Company. The Company has not authorized its use for any other purpose. This Investor Presentation may not be copied or reproduced in whole or in part. By accepting a copy of this Investor Presentation, the recipient agrees that neither it nor any of its representatives, agents or employees shall use it for any other purpose or divulge to any party any confidential information about the Company.

Sheet Get Started
B2: Get Started | D2: NOT MAIN SUBMISSION DELIVERABLE Helps forecast impact of Team 3's reccomendations based on the limited info given by the client and comp based assumptions to measure the revenue and fiscal imapct on unit economics of the given changes
B3: Mauli illustration: supplied £87 AOV proxy; other inputs are reasonable assumptions.
B5: Setup and Timescale
B6: What is the name of your company? | D6: Mauli Rituals | F6: This is used in the Legal Disclaimer sheet, which is purely optional, but something many people choose to include in their projections when they provide them to potential investors
B7: What is your currency? | D7: £ | F7: Model works for any currency, as there are no currency-specific calculations in the model. This label is used in some presentation areas.
B8: What is the first date you want to forecast? | D8: ='Mauli sources'!C8 -> 46327 | F8: First month in the model; if this model is entirely a forecast of the future, input the first month you want to forecast from.
B9: What is the fiscal year end of the first year modeled? | D9: =DATE(YEAR(D8),12,31) -> 46387 | F9: Define the month that is the fiscal year end of the first year in the model. This allows you to set the fiscal years in the model, and thus the # of months in the first year forecasted in the model. The default setting uses a formula to return the year end (in December) from the first month in the forecast. Feel free to overwrite this to set a different fiscal year end, just overwrite the formula with a date.
B11: Historical Cohorts (Optional) | F11: Optional inputs, to use if you have historical cohort data you want to use to generate historical performance and baseline assumptions for future cohorts
B12: What is the first date in your historical data? | D12: =EOMONTH(D14,-24) -> 45596 | F12: The model is built to cover up to 48 months in the past, but (a) you do not have to go back that far, and (b) if you want to go back farther, the model can be edited to do that.
B13: What is the fiscal year end of the first year modeled? | D13: =DATE(YEAR(D12),12,31) -> 45657 | F13: used for the timescale formulas, same as the above
B14: What is the last date in your historical data? | D14: =EOMONTH(D8,-1) -> 46326 | F14: By structural default, this is assumed to be the month prior to the start of the forecast.
B16: Revenue and Marketing Assumptions
B17: ="Average Revenue per Order, new Customer" -> Average Revenue per Order, new Customer | C17: =D$7 -> £ | D17: ='Mauli sources'!C9 -> 87 | F17: Reported blended AOV £87 (challenge brief pp.3,9), unverified. New-customer AOV proxy only; period, VAT, refund and shipping basis unresolved.
B18: ="Average Revenue per Order, repeat Customer" -> Average Revenue per Order, repeat Customer | C18: =D$7 -> £ | D18: =D17 -> 87 | F18: Same £87 proxy for repeat AOV; no measured new/repeat split. Replaces the template 80% illustration, not a client finding.
B19: ="Baseline rate of change in "&B18 -> Baseline rate of change in Average Revenue per Order, repeat Customer | C19: % | D19: 0.1 | F19: this assumes the growth rate in the first month after growth starts, as defined above
B20: ="… where the rate "&IF(D20<0,"declines %",IF(D20>0,"increases %","stays the same"))&" per month" -> … where the rate declines % per month | C20: % | D20: -0.05 | F20: this changes the growth rate over time: you can assume a growth rate that increases over time, stays the same, or decreases (most common)
B22: Cost of Sales | C22: % | D22: 0.25 | F22: per order, as a % of revenues
B23: Additional Cost of Sales | C23: % | D23: 0.1 | F23: per order, as a % of revenues
B24: Additional Cost of Sales | C24: % | D24: 0 | F24: per order, as a % of revenues
B25: ="Baseline rate of change in "&B24 -> Baseline rate of change in Additional Cost of Sales | C25: % | D25: 0 | F25: this assumes the growth rate in the first month after growth starts, as defined above
B26: ="… where the rate "&IF(D26<0,"declines %",IF(D26>0,"increases %","stays the same"))&" per month" -> … where the rate stays the same per month | C26: % | D26: 0 | F26: this changes the growth rate over time: you can assume a growth rate that increases over time, stays the same, or decreases (most common)
B28: Shipping Revenue per order | C28: =D$7 -> £ | D28: 0 | F28: revenue earned from charging for shipping to end customer, per order
B29: Shipping Cost per order | C29: =D$7 -> £ | D29: 0 | F29: costs for shipping to end customer, per order
B31: Customer Acquisition Cost (CAC), new customer | C31: =D$7 -> £ | D31: 30 | F31: ="Customer acquisition cost, per new order" -> Customer acquisition cost, per new order
B32: Customer Acquisition Cost (CAC), repeat customer | C32: =D$7 -> £ | D32: 10 | F32: retention cost per subscriber, per renew cycle. Intention is to include cost to market to existing subscribers to increase retention
B33: ="Baseline rate of change in "&B32 -> Baseline rate of change in Customer Acquisition Cost (CAC), repeat customer | C33: % | D33: 0 | F33: this assumes the rate in the first month after starts, as defined above
B34: ="… where the rate "&IF(D34<0,"declines %",IF(D34>0,"increases %","stays the same"))&" per month" -> … where the rate stays the same per month | C34: % | D34: 0 | F34: this changes the rate over time: you can assume a rate that increases over time, stays the same, or decreases (most common)
B36: Growth and Churn Assumptions
B37: Date to start growth and revenues | D37: =D8 -> 46327 | F37: date to start growth of revenues, used on Forecast sheet in Growth section
B38: New Customers | C38: # | D38: 550 | F38: use the input to change the label, the number input refers to the # new in the first month, as defined above
B39: ="Baseline growth rate in "&B38 -> Baseline growth rate in New Customers | C39: % | D39: 0.9 | F39: this assumes the growth rate in the first month after growth starts, as defined above
B40: ="… where the growth rate "&IF(D40<0,"declines %",IF(D40>0,"increases %","stays the same"))&" per month" -> … where the growth rate declines % per month | C40: % | D40: -0.15 | F40: this changes the growth rate over time: you can assume a growth rate that increases over time, stays the same, or decreases (most common)
B41: Conversion Rate | C41: % | D41: 0.02 | F41: % of website sessions that convert to orders
B42: Customers, beginning of first month | C42: # | D42: 0 | F42: assume the # of new customers that have been acquired prior to the start of the forecast; this is useful if you have an existing base of customers making repeat orders and want to introduce that into the model's forecast of new and repeat orders
B43: Churn rate, per period | C43: % | D43: 0.5 | F43: % of customers that do not make a repeat order, on each repeat cycle
B44: Repeat Cycle | C44: # | D44: 3 | F44: If customers place repeat orders, the # of months to a repeat order. this sets the cadence of repeat orders, and combines with the churn assumption to forecast the # of repeat orders. Important to note is that if you assume a repeat rate, your repeat purchases is bounded by the web sessions and conversion rate. e.g., web sessions * conversion rate = orders. orders - repeat orders = new orders. so if you do not grow web sessions and you assume repeat purchases, it's possible to create a forecast that includes zero orders from new customers. if that happens, reduce your repeat rate, increase your churn, or increase your top-line web sessions growth
B47: After N total customers | C47: # | D47: 0 | F47: optional input to adjust the cohort performance based on total company size, not just per cohort performance
B48: Change cohort performance by | C48: # | D48: 1 | F48: optional adjustment that is applied based on the condition above. "1" means no change, 1.2 means it is 20% better, 0.8 is 20% worse, for example

Sheet Key Reports
B1: ILLUSTRATION ONLY: £87 reported AOV proxy; all other inputs remain assumptions.
B24: Profit and Loss | I24: Orders, per period
B25: by year | I25: Orders from new customers and repeat customers, by year

Sheet Forecast
B2: Forecast
B4: Date | C4: Unit | D4: Note | T4: =EOMONTH('Get Started'!D8,0) -> 46356 | U4: =EOMONTH(EDATE(T4,1),0) -> 46387 | V4: =EOMONTH(EDATE(U4,1),0) -> 46418 | W4: =EOMONTH(EDATE(V4,1),0) -> 46446 | X4: =EOMONTH(EDATE(W4,1),0) -> 46477 | Y4: =EOMONTH(EDATE(X4,1),0) -> 46507 | Z4: =EOMONTH(EDATE(Y4,1),0) -> 46538 | AA4: =EOMONTH(EDATE(Z4,1),0) -> 46568 | AB4: =EOMONTH(EDATE(AA4,1),0) -> 46599 | ... BO4: =EOMONTH(EDATE(BN4,1),0) -> 47787
B5: Timestep | C5: # | D5: where the first month in the period = 0 | T5: 0 | U5: =T5+1 -> 1 | V5: =U5+1 -> 2 | W5: =V5+1 -> 3 | X5: =W5+1 -> 4 | Y5: =X5+1 -> 5 | Z5: =Y5+1 -> 6 | AA5: =Z5+1 -> 7 | AB5: =AA5+1 -> 8 | ... BO5: =BN5+1 -> 47
B6: Month # in Model | C6: # | D6: ="the model structure runs for "&BO6&" months. Month 0 is a pre-structure month, meant to capture opening items that help calculate the first month" -> the model structure runs for 48 months. Month 0 is a pre-structure month, meant to capture opening items that help calculate the first month | T6: 1 | U6: =T6+1 -> 2 | V6: =U6+1 -> 3 | W6: =V6+1 -> 4 | X6: =W6+1 -> 5 | Y6: =X6+1 -> 6 | Z6: =Y6+1 -> 7 | AA6: =Z6+1 -> 8 | AB6: =AA6+1 -> 9 | ... BO6: =BN6+1 -> 48
B7: Fiscal Year | C7: # | D7: the fiscal year can vary from the calendar year, this is calculated based on the assumption for fiscal year end | T7: {=IF(EOMONTH(T4,0)<=EOMONTH('Get Started'!$D9,0),YEAR('Get Started'!$D9),IF(T6<=(MONTH('Get Started'!$D9)-MONTH('Get Started'!$D8)),YEAR('Get Started'!$D9),IF(T6<=12,YEAR('Get Started'!$D9)+1,IFERROR(INDEX(S7:$T7,0,MATCH(T5-12,S5:$T5,0)),0)+1)))} -> 2026 | U7: {=IF(EOMONTH(U4,0)<=EOMONTH('Get Started'!$D9,0),YEAR('Get Started'!$D9),IF(U6<=(MONTH('Get Started'!$D9)-MONTH('Get Started'!$D8)),YEAR('Get Started'!$D9),IF(U6<=12,YEAR('Get Started'!$D9)+1,IFERROR(INDEX(T7:$T7,0,MATCH(U5-12,T5:$T5,0)),0)+1)))} -> 2026 | V7: {=IF(EOMONTH(V4,0)<=EOMONTH('Get Started'!$D9,0),YEAR('Get Started'!$D9),IF(V6<=(MONTH('Get Started'!$D9)-MONTH('Get Started'!$D8)),YEAR('Get Started'!$D9),IF(V6<=12,YEAR('Get Started'!$D9)+1,IFERROR(INDEX($T7:U7,0,MATCH(V5-12,$T5:U5,0)),0)+1)))} -> 2027 | W7: {=IF(EOMONTH(W4,0)<=EOMONTH('Get Started'!$D9,0),YEAR('Get Started'!$D9),IF(W6<=(MONTH('Get Started'!$D9)-MONTH('Get Started'!$D8)),YEAR('Get Started'!$D9),IF(W6<=12,YEAR('Get Started'!$D9)+1,IFERROR(INDEX($T7:V7,0,MATCH(W5-12,$T5:V5,0)),0)+1)))} -> 2027 | X7: {=IF(EOMONTH(X4,0)<=EOMONTH('Get Started'!$D9,0),YEAR('Get Started'!$D9),IF(X6<=(MONTH('Get Started'!$D9)-MONTH('Get Started'!$D8)),YEAR('Get Started'!$D9),IF(X6<=12,YEAR('Get Started'!$D9)+1,IFERROR(INDEX($T7:W7,0,MATCH(X5-12,$T5:W5,0)),0)+1)))} -> 2027 | Y7: {=IF(EOMONTH(Y4,0)<=EOMONTH('Get Started'!$D9,0),YEAR('Get Started'!$D9),IF(Y6<=(MONTH('Get Started'!$D9)-MONTH('Get Started'!$D8)),YEAR('Get Started'!$D9),IF(Y6<=12,YEAR('Get Started'!$D9)+1,IFERROR(INDEX($T7:X7,0,MATCH(Y5-12,$T5:X5,0)),0)+1)))} -> 2027 | Z7: {=IF(EOMONTH(Z4,0)<=EOMONTH('Get Started'!$D9,0),YEAR('Get Started'!$D9),IF(Z6<=(MONTH('Get Started'!$D9)-MONTH('Get Started'!$D8)),YEAR('Get Started'!$D9),IF(Z6<=12,YEAR('Get Started'!$D9)+1,IFERROR(INDEX($T7:Y7,0,MATCH(Z5-12,$T5:Y5,0)),0)+1)))} -> 2027 | AA7: {=IF(EOMONTH(AA4,0)<=EOMONTH('Get Started'!$D9,0),YEAR('Get Started'!$D9),IF(AA6<=(MONTH('Get Started'!$D9)-MONTH('Get Started'!$D8)),YEAR('Get Started'!$D9),IF(AA6<=12,YEAR('Get Started'!$D9)+1,IFERROR(INDEX($T7:Z7,0,MATCH(AA5-12,$T5:Z5,0)),0)+1)))} -> 2027 | AB7: {=IF(EOMONTH(AB4,0)<=EOMONTH('Get Started'!$D9,0),YEAR('Get Started'!$D9),IF(AB6<=(MONTH('Get Started'!$D9)-MONTH('Get Started'!$D8)),YEAR('Get Started'!$D9),IF(AB6<=12,YEAR('Get Started'!$D9)+1,IFERROR(INDEX($T7:AA7,0,MATCH(AB5-12,$T5:AA5,0)),0)+1)))} -> 2027 | AC7: {=IF(EOMONTH(AC4,0)<=EOMONTH('Get Started'!$D9,0),YEAR('Get Started'!$D9),IF(AC6<=(MONTH('Get Started'!$D9)-MONTH('Get Started'!$D8)),YEAR('Get Started'!$D9),IF(AC6<=12,YEAR('Get Started'!$D9)+1,IFERROR(INDEX($T7:AB7,0,MATCH(AC5-12,$T5:AB5,0)),0)+1)))} -> 2027 | ... BO7: {=IF(EOMONTH(BO4,0)<=EOMONTH('Get Started'!$D9,0),YEAR('Get Started'!$D9),IF(BO6<=(MONTH('Get Started'!$D9)-MONTH('Get Started'!$D8)),YEAR('Get Started'!$D9),IF(BO6<=12,YEAR('Get Started'!$D9)+1,IFERROR(INDEX($T7:BN7,0,MATCH(BO5-12,$T5:BN5,0)),0)+1)))} -> 2030
B8: Quarter in Fiscal Year | C8: text | D8: the quarters of the year vary according by the fiscal year end | T8: =IF(OR(T11=3,T11=2,T11=1),"Q1",IF(OR(T11=6,T11=5,T11=4),"Q2",IF(OR(T11=9,T11=8,T11=7),"Q3","Q4"))) -> Q4 | U8: =IF(OR(U11=3,U11=2,U11=1),"Q1",IF(OR(U11=6,U11=5,U11=4),"Q2",IF(OR(U11=9,U11=8,U11=7),"Q3","Q4"))) -> Q4 | V8: =IF(OR(V11=3,V11=2,V11=1),"Q1",IF(OR(V11=6,V11=5,V11=4),"Q2",IF(OR(V11=9,V11=8,V11=7),"Q3","Q4"))) -> Q1 | W8: =IF(OR(W11=3,W11=2,W11=1),"Q1",IF(OR(W11=6,W11=5,W11=4),"Q2",IF(OR(W11=9,W11=8,W11=7),"Q3","Q4"))) -> Q1 | X8: =IF(OR(X11=3,X11=2,X11=1),"Q1",IF(OR(X11=6,X11=5,X11=4),"Q2",IF(OR(X11=9,X11=8,X11=7),"Q3","Q4"))) -> Q1 | Y8: =IF(OR(Y11=3,Y11=2,Y11=1),"Q1",IF(OR(Y11=6,Y11=5,Y11=4),"Q2",IF(OR(Y11=9,Y11=8,Y11=7),"Q3","Q4"))) -> Q2 | Z8: =IF(OR(Z11=3,Z11=2,Z11=1),"Q1",IF(OR(Z11=6,Z11=5,Z11=4),"Q2",IF(OR(Z11=9,Z11=8,Z11=7),"Q3","Q4"))) -> Q2 | AA8: =IF(OR(AA11=3,AA11=2,AA11=1),"Q1",IF(OR(AA11=6,AA11=5,AA11=4),"Q2",IF(OR(AA11=9,AA11=8,AA11=7),"Q3","Q4"))) -> Q2 | ... BO8: =IF(OR(BO11=3,BO11=2,BO11=1),"Q1",IF(OR(BO11=6,BO11=5,BO11=4),"Q2",IF(OR(BO11=9,BO11=8,BO11=7),"Q3","Q4"))) -> Q4
B9: Quarter / Year | C9: text | D9: quarters and year, reported in text form for some charts and graphs | T9: =T8&" "&T7 -> Q4 2026 | U9: =U8&" "&U7 -> Q4 2026 | V9: =V8&" "&V7 -> Q1 2027 | W9: =W8&" "&W7 -> Q1 2027 | X9: =X8&" "&X7 -> Q1 2027 | Y9: =Y8&" "&Y7 -> Q2 2027 | Z9: =Z8&" "&Z7 -> Q2 2027 | AA9: =AA8&" "&AA7 -> Q2 2027 | ... BO9: =BO8&" "&BO7 -> Q4 2030
B10: Month (Text) | C10: text | D10: the month of the calendar year, used for reporting and seasonality calculations | T10: =TEXT(T4,"mmmm") -> November | U10: =TEXT(U4,"mmmm") -> December | V10: =TEXT(V4,"mmmm") -> January | W10: =TEXT(W4,"mmmm") -> February | X10: =TEXT(X4,"mmmm") -> March | Y10: =TEXT(Y4,"mmmm") -> April | Z10: =TEXT(Z4,"mmmm") -> May | AA10: =TEXT(AA4,"mmmm") -> June | ... BO10: =TEXT(BO4,"mmmm") -> October
B11: Month # in Fiscal year | C11: # | D11: the month # in the fiscal year. This rolls over to 1 at the start of each fiscal year | T11: =IF(MOD(MONTH(T4)+12-MONTH('Get Started'!$D9),12)=0,12,MOD(MONTH(T4)+12-MONTH('Get Started'!$D9),12)) -> 11 | U11: =IF(MOD(MONTH(U4)+12-MONTH('Get Started'!$D9),12)=0,12,MOD(MONTH(U4)+12-MONTH('Get Started'!$D9),12)) -> 12 | V11: =IF(MOD(MONTH(V4)+12-MONTH('Get Started'!$D9),12)=0,12,MOD(MONTH(V4)+12-MONTH('Get Started'!$D9),12)) -> 1 | W11: =IF(MOD(MONTH(W4)+12-MONTH('Get Started'!$D9),12)=0,12,MOD(MONTH(W4)+12-MONTH('Get Started'!$D9),12)) -> 2 | X11: =IF(MOD(MONTH(X4)+12-MONTH('Get Started'!$D9),12)=0,12,MOD(MONTH(X4)+12-MONTH('Get Started'!$D9),12)) -> 3 | Y11: =IF(MOD(MONTH(Y4)+12-MONTH('Get Started'!$D9),12)=0,12,MOD(MONTH(Y4)+12-MONTH('Get Started'!$D9),12)) -> 4 | Z11: =IF(MOD(MONTH(Z4)+12-MONTH('Get Started'!$D9),12)=0,12,MOD(MONTH(Z4)+12-MONTH('Get Started'!$D9),12)) -> 5 | AA11: =IF(MOD(MONTH(AA4)+12-MONTH('Get Started'!$D9),12)=0,12,MOD(MONTH(AA4)+12-MONTH('Get Started'!$D9),12)) -> 6 | ... BO11: =IF(MOD(MONTH(BO4)+12-MONTH('Get Started'!$D9),12)=0,12,MOD(MONTH(BO4)+12-MONTH('Get Started'!$D9),12)) -> 10
B12: Year of Operations | C12: # | D12: the year of operations. Used for some reports based on time of operations, not calendar year | T12: 1 | U12: =T12 -> 1 | V12: =U12 -> 1 | W12: =V12 -> 1 | X12: =W12 -> 1 | Y12: =X12 -> 1 | Z12: =Y12 -> 1 | AA12: =Z12 -> 1 | AB12: =AA12 -> 1 | ... AE12: =AD12 -> 1 | AF12: =T12+1 -> 2 | AG12: =U12+1 -> 2 | AH12: =V12+1 -> 2 | AI12: =W12+1 -> 2 | AJ12: =X12+1 -> 2 | AK12: =Y12+1 -> 2 | AL12: =Z12+1 -> 2 | AM12: =AA12+1 -> 2 | ... BO12: =BC12+1 -> 4
B15: Revenue and Marketing Assumptions
B16: ='Get Started'!B17 -> Average Revenue per Order, new Customer | C16: ='Get Started'!D$7 -> £ | D16: ='Get Started'!F17 -> Reported blended AOV £87 (challenge brief pp.3,9), unverified. New-customer AOV proxy only; period, VAT, refund and shipping basis unresolved. | H16: average | I16: =IF(H16=Forecast!$H$195,T16,IF(H16=Forecast!$H$196,BO16,IF(H16=Forecast!$H$197,SUM(T16:BO16),IF(H16=Forecast!$H$198,AVERAGE(T16:BO16),0)))) -> 87 | T16: ='Get Started'!$D17 -> 87 | U16: ='Get Started'!$D17 -> 87 | V16: ='Get Started'!$D17 -> 87 | W16: ='Get Started'!$D17 -> 87 | X16: ='Get Started'!$D17 -> 87 | Y16: ='Get Started'!$D17 -> 87 | Z16: ='Get Started'!$D17 -> 87 | AA16: ='Get Started'!$D17 -> 87 | ... BO16: ='Get Started'!$D17 -> 87
B17: ='Get Started'!B18 -> Average Revenue per Order, repeat Customer | C17: ='Get Started'!D$7 -> £ | D17: ='Get Started'!F18 -> Same £87 proxy for repeat AOV; no measured new/repeat split. Replaces the template 80% illustration, not a client finding. | H17: average | I17: =IF(H17=Forecast!$H$195,T17,IF(H17=Forecast!$H$196,BO17,IF(H17=Forecast!$H$197,SUM(T17:BO17),IF(H17=Forecast!$H$198,AVERAGE(T17:BO17),0)))) -> 87 | T17: ='Get Started'!$D18 -> 87 | U17: ='Get Started'!$D18 -> 87 | V17: ='Get Started'!$D18 -> 87 | W17: ='Get Started'!$D18 -> 87 | X17: ='Get Started'!$D18 -> 87 | Y17: ='Get Started'!$D18 -> 87 | Z17: ='Get Started'!$D18 -> 87 | AA17: ='Get Started'!$D18 -> 87 | ... BO17: ='Get Started'!$D18 -> 87
B18: Starting rate of change, Average Revenue per Order | C18: % | D18: ='Get Started'!F19 -> this assumes the growth rate in the first month after growth starts, as defined above | H18: average | I18: =IF(H18=Forecast!$H$195,T18,IF(H18=Forecast!$H$196,BO18,IF(H18=Forecast!$H$197,SUM(T18:BO18),IF(H18=Forecast!$H$198,AVERAGE(T18:BO18),0)))) -> 0.1 | T18: ='Get Started'!$D19 -> 0.1 | U18: ='Get Started'!$D19 -> 0.1 | V18: ='Get Started'!$D19 -> 0.1 | W18: ='Get Started'!$D19 -> 0.1 | X18: ='Get Started'!$D19 -> 0.1 | Y18: ='Get Started'!$D19 -> 0.1 | Z18: ='Get Started'!$D19 -> 0.1 | AA18: ='Get Started'!$D19 -> 0.1 | ... BO18: ='Get Started'!$D19 -> 0.1
B19: Rate of change, Average Revenue per Order | C19: % | D19: ='Get Started'!F20 -> this changes the growth rate over time: you can assume a growth rate that increases over time, stays the same, or decreases (most common) | H19: average | I19: =IF(H19=Forecast!$H$195,T19,IF(H19=Forecast!$H$196,BO19,IF(H19=Forecast!$H$197,SUM(T19:BO19),IF(H19=Forecast!$H$198,AVERAGE(T19:BO19),0)))) -> -0.05 | T19: ='Get Started'!$D20 -> -0.05 | U19: ='Get Started'!$D20 -> -0.05 | V19: ='Get Started'!$D20 -> -0.05 | W19: ='Get Started'!$D20 -> -0.05 | X19: ='Get Started'!$D20 -> -0.05 | Y19: ='Get Started'!$D20 -> -0.05 | Z19: ='Get Started'!$D20 -> -0.05 | AA19: ='Get Started'!$D20 -> -0.05 | ... BO19: ='Get Started'!$D20 -> -0.05
B20: ='Get Started'!B22 -> Cost of Sales | C20: % | D20: ='Get Started'!F22 -> per order, as a % of revenues | H20: average | I20: =IF(H20=Forecast!$H$195,T20,IF(H20=Forecast!$H$196,BO20,IF(H20=Forecast!$H$197,SUM(T20:BO20),IF(H20=Forecast!$H$198,AVERAGE(T20:BO20),0)))) -> 0.25 | T20: ='Get Started'!$D22 -> 0.25 | U20: ='Get Started'!$D22 -> 0.25 | V20: ='Get Started'!$D22 -> 0.25 | W20: ='Get Started'!$D22 -> 0.25 | X20: ='Get Started'!$D22 -> 0.25 | Y20: ='Get Started'!$D22 -> 0.25 | Z20: ='Get Started'!$D22 -> 0.25 | AA20: ='Get Started'!$D22 -> 0.25 | ... BO20: ='Get Started'!$D22 -> 0.25
B21: ='Get Started'!B23 -> Additional Cost of Sales | C21: % | D21: ='Get Started'!F23 -> per order, as a % of revenues | H21: average | I21: =IF(H21=Forecast!$H$195,T21,IF(H21=Forecast!$H$196,BO21,IF(H21=Forecast!$H$197,SUM(T21:BO21),IF(H21=Forecast!$H$198,AVERAGE(T21:BO21),0)))) -> 0.1 | T21: ='Get Started'!$D23 -> 0.1 | U21: ='Get Started'!$D23 -> 0.1 | V21: ='Get Started'!$D23 -> 0.1 | W21: ='Get Started'!$D23 -> 0.1 | X21: ='Get Started'!$D23 -> 0.1 | Y21: ='Get Started'!$D23 -> 0.1 | Z21: ='Get Started'!$D23 -> 0.1 | AA21: ='Get Started'!$D23 -> 0.1 | ... BO21: ='Get Started'!$D23 -> 0.1
B22: ='Get Started'!B24 -> Additional Cost of Sales | C22: % | D22: ='Get Started'!F24 -> per order, as a % of revenues | H22: average | I22: =IF(H22=Forecast!$H$195,T22,IF(H22=Forecast!$H$196,BO22,IF(H22=Forecast!$H$197,SUM(T22:BO22),IF(H22=Forecast!$H$198,AVERAGE(T22:BO22),0)))) -> 0 | T22: ='Get Started'!$D24 -> 0 | U22: ='Get Started'!$D24 -> 0 | V22: ='Get Started'!$D24 -> 0 | W22: ='Get Started'!$D24 -> 0 | X22: ='Get Started'!$D24 -> 0 | Y22: ='Get Started'!$D24 -> 0 | Z22: ='Get Started'!$D24 -> 0 | AA22: ='Get Started'!$D24 -> 0 | ... BO22: ='Get Started'!$D24 -> 0
B23: Starting rate of change, Cost of Sales | C23: % | D23: ='Get Started'!F25 -> this assumes the growth rate in the first month after growth starts, as defined above | H23: average | I23: =IF(H23=Forecast!$H$195,T23,IF(H23=Forecast!$H$196,BO23,IF(H23=Forecast!$H$197,SUM(T23:BO23),IF(H23=Forecast!$H$198,AVERAGE(T23:BO23),0)))) -> 0 | T23: ='Get Started'!$D25 -> 0 | U23: ='Get Started'!$D25 -> 0 | V23: ='Get Started'!$D25 -> 0 | W23: ='Get Started'!$D25 -> 0 | X23: ='Get Started'!$D25 -> 0 | Y23: ='Get Started'!$D25 -> 0 | Z23: ='Get Started'!$D25 -> 0 | AA23: ='Get Started'!$D25 -> 0 | ... BO23: ='Get Started'!$D25 -> 0
B24: Rate of change, Cost of Sales | C24: % | D24: ='Get Started'!F26 -> this changes the growth rate over time: you can assume a growth rate that increases over time, stays the same, or decreases (most common) | H24: average | I24: =IF(H24=Forecast!$H$195,T24,IF(H24=Forecast!$H$196,BO24,IF(H24=Forecast!$H$197,SUM(T24:BO24),IF(H24=Forecast!$H$198,AVERAGE(T24:BO24),0)))) -> 0 | T24: ='Get Started'!$D26 -> 0 | U24: ='Get Started'!$D26 -> 0 | V24: ='Get Started'!$D26 -> 0 | W24: ='Get Started'!$D26 -> 0 | X24: ='Get Started'!$D26 -> 0 | Y24: ='Get Started'!$D26 -> 0 | Z24: ='Get Started'!$D26 -> 0 | AA24: ='Get Started'!$D26 -> 0 | ... BO24: ='Get Started'!$D26 -> 0
B25: ='Get Started'!B28 -> Shipping Revenue per order | C25: ='Get Started'!D$7 -> £ | D25: ='Get Started'!F28 -> revenue earned from charging for shipping to end customer, per order | H25: average | I25: =IF(H25=Forecast!$H$195,T25,IF(H25=Forecast!$H$196,BO25,IF(H25=Forecast!$H$197,SUM(T25:BO25),IF(H25=Forecast!$H$198,AVERAGE(T25:BO25),0)))) -> 0 | T25: ='Get Started'!$D28 -> 0 | U25: ='Get Started'!$D28 -> 0 | V25: ='Get Started'!$D28 -> 0 | W25: ='Get Started'!$D28 -> 0 | X25: ='Get Started'!$D28 -> 0 | Y25: ='Get Started'!$D28 -> 0 | Z25: ='Get Started'!$D28 -> 0 | AA25: ='Get Started'!$D28 -> 0 | ... BO25: ='Get Started'!$D28 -> 0
B26: ='Get Started'!B29 -> Shipping Cost per order | C26: ='Get Started'!D$7 -> £ | D26: ='Get Started'!F29 -> costs for shipping to end customer, per order | H26: average | I26: =IF(H26=Forecast!$H$195,T26,IF(H26=Forecast!$H$196,BO26,IF(H26=Forecast!$H$197,SUM(T26:BO26),IF(H26=Forecast!$H$198,AVERAGE(T26:BO26),0)))) -> 0 | T26: ='Get Started'!$D29 -> 0 | U26: ='Get Started'!$D29 -> 0 | V26: ='Get Started'!$D29 -> 0 | W26: ='Get Started'!$D29 -> 0 | X26: ='Get Started'!$D29 -> 0 | Y26: ='Get Started'!$D29 -> 0 | Z26: ='Get Started'!$D29 -> 0 | AA26: ='Get Started'!$D29 -> 0 | ... BO26: ='Get Started'!$D29 -> 0
B27: ='Get Started'!B31 -> Customer Acquisition Cost (CAC), new customer | C27: ='Get Started'!D$7 -> £ | D27: ='Get Started'!F31 -> Customer acquisition cost, per new order | H27: average | I27: =IF(H27=Forecast!$H$195,T27,IF(H27=Forecast!$H$196,BO27,IF(H27=Forecast!$H$197,SUM(T27:BO27),IF(H27=Forecast!$H$198,AVERAGE(T27:BO27),0)))) -> 30 | T27: ='Get Started'!$D31 -> 30 | U27: ='Get Started'!$D31 -> 30 | V27: ='Get Started'!$D31 -> 30 | W27: ='Get Started'!$D31 -> 30 | X27: ='Get Started'!$D31 -> 30 | Y27: ='Get Started'!$D31 -> 30 | Z27: ='Get Started'!$D31 -> 30 | AA27: ='Get Started'!$D31 -> 30 | ... BO27: ='Get Started'!$D31 -> 30
B28: ='Get Started'!B32 -> Customer Acquisition Cost (CAC), repeat customer | C28: ='Get Started'!D$7 -> £ | D28: ='Get Started'!F32 -> retention cost per subscriber, per renew cycle. Intention is to include cost to market to existing subscribers to increase retention | H28: average | I28: =IF(H28=Forecast!$H$195,T28,IF(H28=Forecast!$H$196,BO28,IF(H28=Forecast!$H$197,SUM(T28:BO28),IF(H28=Forecast!$H$198,AVERAGE(T28:BO28),0)))) -> 10 | T28: ='Get Started'!$D32 -> 10 | U28: ='Get Started'!$D32 -> 10 | V28: ='Get Started'!$D32 -> 10 | W28: ='Get Started'!$D32 -> 10 | X28: ='Get Started'!$D32 -> 10 | Y28: ='Get Started'!$D32 -> 10 | Z28: ='Get Started'!$D32 -> 10 | AA28: ='Get Started'!$D32 -> 10 | ... BO28: ='Get Started'!$D32 -> 10
B29: Starting rate of change, CAC | C29: % | D29: ='Get Started'!F33 -> this assumes the rate in the first month after starts, as defined above | H29: average | I29: =IF(H29=Forecast!$H$195,T29,IF(H29=Forecast!$H$196,BO29,IF(H29=Forecast!$H$197,SUM(T29:BO29),IF(H29=Forecast!$H$198,AVERAGE(T29:BO29),0)))) -> 0 | T29: ='Get Started'!$D33 -> 0 | U29: ='Get Started'!$D33 -> 0 | V29: ='Get Started'!$D33 -> 0 | W29: ='Get Started'!$D33 -> 0 | X29: ='Get Started'!$D33 -> 0 | Y29: ='Get Started'!$D33 -> 0 | Z29: ='Get Started'!$D33 -> 0 | AA29: ='Get Started'!$D33 -> 0 | ... BO29: ='Get Started'!$D33 -> 0
B30: Rate of change, CAC | C30: % | D30: ='Get Started'!F34 -> this changes the rate over time: you can assume a rate that increases over time, stays the same, or decreases (most common) | H30: average | I30: =IF(H30=Forecast!$H$195,T30,IF(H30=Forecast!$H$196,BO30,IF(H30=Forecast!$H$197,SUM(T30:BO30),IF(H30=Forecast!$H$198,AVERAGE(T30:BO30),0)))) -> 0 | T30: ='Get Started'!$D34 -> 0 | U30: ='Get Started'!$D34 -> 0 | V30: ='Get Started'!$D34 -> 0 | W30: ='Get Started'!$D34 -> 0 | X30: ='Get Started'!$D34 -> 0 | Y30: ='Get Started'!$D34 -> 0 | Z30: ='Get Started'!$D34 -> 0 | AA30: ='Get Started'!$D34 -> 0 | ... BO30: ='Get Started'!$D34 -> 0
B32: Growth and Churn Assumptions
B33: ='Get Started'!B37 -> Date to start growth and revenues | C33: # | D33: ='Get Started'!F37 -> date to start growth of revenues, used on Forecast sheet in Growth section | H33: initial | I33: =IF(H33=Forecast!$H$195,T33,IF(H33=Forecast!$H$196,BO33,IF(H33=Forecast!$H$197,SUM(T33:BO33),IF(H33=Forecast!$H$198,AVERAGE(T33:BO33),0)))) -> 46327 | T33: ='Get Started'!$D37 -> 46327 | U33: ='Get Started'!$D37 -> 46327 | V33: ='Get Started'!$D37 -> 46327 | W33: ='Get Started'!$D37 -> 46327 | X33: ='Get Started'!$D37 -> 46327 | Y33: ='Get Started'!$D37 -> 46327 | Z33: ='Get Started'!$D37 -> 46327 | AA33: ='Get Started'!$D37 -> 46327 | ... BO33: ='Get Started'!$D37 -> 46327
B34: ='Get Started'!B38 -> New Customers | C34: # | D34: ='Get Started'!F38 -> use the input to change the label, the number input refers to the # new in the first month, as defined above | H34: average | I34: =IF(H34=Forecast!$H$195,T34,IF(H34=Forecast!$H$196,BO34,IF(H34=Forecast!$H$197,SUM(T34:BO34),IF(H34=Forecast!$H$198,AVERAGE(T34:BO34),0)))) -> 550 | T34: ='Get Started'!$D38 -> 550 | U34: ='Get Started'!$D38 -> 550 | V34: ='Get Started'!$D38 -> 550 | W34: ='Get Started'!$D38 -> 550 | X34: ='Get Started'!$D38 -> 550 | Y34: ='Get Started'!$D38 -> 550 | Z34: ='Get Started'!$D38 -> 550 | AA34: ='Get Started'!$D38 -> 550 | ... BO34: ='Get Started'!$D38 -> 550
B35: Starting growth rate, new subscribers | C35: % | D35: ='Get Started'!F39 -> this assumes the growth rate in the first month after growth starts, as defined above | H35: average | I35: =IF(H35=Forecast!$H$195,T35,IF(H35=Forecast!$H$196,BO35,IF(H35=Forecast!$H$197,SUM(T35:BO35),IF(H35=Forecast!$H$198,AVERAGE(T35:BO35),0)))) -> 0.9 | T35: ='Get Started'!$D39 -> 0.9 | U35: ='Get Started'!$D39 -> 0.9 | V35: ='Get Started'!$D39 -> 0.9 | W35: ='Get Started'!$D39 -> 0.9 | X35: ='Get Started'!$D39 -> 0.9 | Y35: ='Get Started'!$D39 -> 0.9 | Z35: ='Get Started'!$D39 -> 0.9 | AA35: ='Get Started'!$D39 -> 0.9 | ... BO35: ='Get Started'!$D39 -> 0.9
B36: Change in Growth Rate in new subscribers | C36: % | D36: ='Get Started'!F40 -> this changes the growth rate over time: you can assume a growth rate that increases over time, stays the same, or decreases (most common) | H36: average | I36: =IF(H36=Forecast!$H$195,T36,IF(H36=Forecast!$H$196,BO36,IF(H36=Forecast!$H$197,SUM(T36:BO36),IF(H36=Forecast!$H$198,AVERAGE(T36:BO36),0)))) -> -0.15 | T36: ='Get Started'!$D40 -> -0.15 | U36: ='Get Started'!$D40 -> -0.15 | V36: ='Get Started'!$D40 -> -0.15 | W36: ='Get Started'!$D40 -> -0.15 | X36: ='Get Started'!$D40 -> -0.15 | Y36: ='Get Started'!$D40 -> -0.15 | Z36: ='Get Started'!$D40 -> -0.15 | AA36: ='Get Started'!$D40 -> -0.15 | ... BO36: ='Get Started'!$D40 -> -0.15
B37: ='Get Started'!B41 -> Conversion Rate | C37: # | D37: ='Get Started'!F41 -> % of website sessions that convert to orders | H37: average | I37: =IF(H37=Forecast!$H$195,T37,IF(H37=Forecast!$H$196,BO37,IF(H37=Forecast!$H$197,SUM(T37:BO37),IF(H37=Forecast!$H$198,AVERAGE(T37:BO37),0)))) -> 0.02 | T37: ='Get Started'!$D41 -> 0.02 | U37: ='Get Started'!$D41 -> 0.02 | V37: ='Get Started'!$D41 -> 0.02 | W37: ='Get Started'!$D41 -> 0.02 | X37: ='Get Started'!$D41 -> 0.02 | Y37: ='Get Started'!$D41 -> 0.02 | Z37: ='Get Started'!$D41 -> 0.02 | AA37: ='Get Started'!$D41 -> 0.02 | ... BO37: ='Get Started'!$D41 -> 0.02
B38: ='Get Started'!B42 -> Customers, beginning of first month | C38: # | D38: ='Get Started'!F42 -> assume the # of new customers that have been acquired prior to the start of the forecast; this is useful if you have an existing base of customers making repeat orders and want to introduce that into the model's forecast of new and repeat orders | H38: average | I38: =IF(H38=Forecast!$H$195,T38,IF(H38=Forecast!$H$196,BO38,IF(H38=Forecast!$H$197,SUM(T38:BO38),IF(H38=Forecast!$H$198,AVERAGE(T38:BO38),0)))) -> 0 | T38: ='Get Started'!$D42 -> 0 | U38: ='Get Started'!$D42 -> 0 | V38: ='Get Started'!$D42 -> 0 | W38: ='Get Started'!$D42 -> 0 | X38: ='Get Started'!$D42 -> 0 | Y38: ='Get Started'!$D42 -> 0 | Z38: ='Get Started'!$D42 -> 0 | AA38: ='Get Started'!$D42 -> 0 | ... BO38: ='Get Started'!$D42 -> 0
B39: ='Get Started'!B43 -> Churn rate, per period | C39: % | D39: ='Get Started'!F43 -> % of customers that do not make a repeat order, on each repeat cycle | H39: average | I39: =IF(H39=Forecast!$H$195,T39,IF(H39=Forecast!$H$196,BO39,IF(H39=Forecast!$H$197,SUM(T39:BO39),IF(H39=Forecast!$H$198,AVERAGE(T39:BO39),0)))) -> 0.5 | T39: ='Get Started'!$D43 -> 0.5 | U39: ='Get Started'!$D43 -> 0.5 | V39: ='Get Started'!$D43 -> 0.5 | W39: ='Get Started'!$D43 -> 0.5 | X39: ='Get Started'!$D43 -> 0.5 | Y39: ='Get Started'!$D43 -> 0.5 | Z39: ='Get Started'!$D43 -> 0.5 | AA39: ='Get Started'!$D43 -> 0.5 | ... BO39: ='Get Started'!$D43 -> 0.5
B40: ='Get Started'!B44 -> Repeat Cycle | C40: # | D40: =" "&LOWER('Get Started'!F44) -> if customers place repeat orders, the # of months to a repeat order. this sets the cadence of repeat orders, and combines with the churn assumption to forecast the # of repeat orders. important to note is that if you assume a repeat rate, your repeat purchases is bounded by the web sessions and conversion rate. e.g., web sessions * conversion rate = orders. orders - repeat orders = new orders. so if you do not grow web sessions and you assume repeat purchases, it's possible to create a forecast that includes zero orders from new customers. if that happens, reduce your repeat rate, increase your churn, or increase your top-line web sessions growth | H40: average | I40: =IF(H40=Forecast!$H$195,T40,IF(H40=Forecast!$H$196,BO40,IF(H40=Forecast!$H$197,SUM(T40:BO40),IF(H40=Forecast!$H$198,AVERAGE(T40:BO40),0)))) -> 3 | T40: ='Get Started'!$D44 -> 3 | U40: ='Get Started'!$D44 -> 3 | V40: ='Get Started'!$D44 -> 3 | W40: ='Get Started'!$D44 -> 3 | X40: ='Get Started'!$D44 -> 3 | Y40: ='Get Started'!$D44 -> 3 | Z40: ='Get Started'!$D44 -> 3 | AA40: ='Get Started'!$D44 -> 3 | ... BO40: ='Get Started'!$D44 -> 3
B41: Orders, per customer, as a # per 1 customer | C41: # | D41: calculated from the churn rate and repeat cycle inputs | H41: sum | I41: =IF(H41=Forecast!$H$195,T41,IF(H41=Forecast!$H$196,BO41,IF(H41=Forecast!$H$197,SUM(T41:BO41),IF(H41=Forecast!$H$198,AVERAGE(T41:BO41),0)))) -> 1.9999695 | T41: =IF(T6=1,1,IF(MOD(T5,T40)=0,(1-T39)*IF(T5<T40,0, OFFSET(T41,,-1*T40)),0)) -> 1 | U41: =IF(U6=1,1,IF(MOD(U5,U40)=0,(1-U39)*IF(U5<U40,0, OFFSET(U41,,-1*U40)),0)) -> 0 | V41: =IF(V6=1,1,IF(MOD(V5,V40)=0,(1-V39)*IF(V5<V40,0, OFFSET(V41,,-1*V40)),0)) -> 0 | W41: =IF(W6=1,1,IF(MOD(W5,W40)=0,(1-W39)*IF(W5<W40,0, OFFSET(W41,,-1*W40)),0)) -> 0.5 | X41: =IF(X6=1,1,IF(MOD(X5,X40)=0,(1-X39)*IF(X5<X40,0, OFFSET(X41,,-1*X40)),0)) -> 0 | Y41: =IF(Y6=1,1,IF(MOD(Y5,Y40)=0,(1-Y39)*IF(Y5<Y40,0, OFFSET(Y41,,-1*Y40)),0)) -> 0 | Z41: =IF(Z6=1,1,IF(MOD(Z5,Z40)=0,(1-Z39)*IF(Z5<Z40,0, OFFSET(Z41,,-1*Z40)),0)) -> 0.25 | AA41: =IF(AA6=1,1,IF(MOD(AA5,AA40)=0,(1-AA39)*IF(AA5<AA40,0, OFFSET(AA41,,-1*AA40)),0)) -> 0 | ... BO41: =IF(BO6=1,1,IF(MOD(BO5,BO40)=0,(1-BO39)*IF(BO5<BO40,0, OFFSET(BO41,,-1*BO40)),0)) -> 0
B42: Orders, per customer, as a # per 1 customer | C42: # | D42: historical average | H42: sum | I42: =IF(H42=Forecast!$H$195,T42,IF(H42=Forecast!$H$196,BO42,IF(H42=Forecast!$H$197,SUM(T42:BO42),IF(H42=Forecast!$H$198,AVERAGE(T42:BO42),0)))) -> 4.051061 | T42: =Historicals!T64 -> 1 | U42: =Historicals!U64 -> 0.64761384 | V42: =Historicals!V64 -> 0.586256 | W42: =Historicals!W64 -> 0.42200024 | X42: =Historicals!X64 -> 0.32424205 | Y42: =Historicals!Y64 -> 0.24920418 | Z42: =Historicals!Z64 -> 0.19158545 | AA42: =Historicals!AA64 -> 0.14732616 | ... BO42: =Historicals!BO64 -> 0
B43: Orders, per customer, as a # per 1 customer | C43: # | D43: manual input | H43: sum | I43: =IF(H43=Forecast!$H$195,T43,IF(H43=Forecast!$H$196,BO43,IF(H43=Forecast!$H$197,SUM(T43:BO43),IF(H43=Forecast!$H$198,AVERAGE(T43:BO43),0)))) -> 1.9999999 | T43: 1 | U43: 0 | V43: =T43*0.5 -> 0.5 | W43: =U43*0.5 -> 0 | X43: =V43*0.5 -> 0.25 | Y43: =W43*0.5 -> 0 | Z43: =X43*0.5 -> 0.125 | AA43: =Y43*0.5 -> 0 | AB43: =Z43*0.5 -> 0.0625 | AC43: =AA43*0.5 -> 0 | ... BO43: =BM43*0.5 -> 0
B44: Orders per 1 New Customer (the retention curve used in the model) | C44: # | D44: calculated from the churn rate and repeat cycle inputs | F44: 1 | G44: x | H44: sum | I44: =IF(H44=Forecast!$H$195,T44,IF(H44=Forecast!$H$196,BO44,IF(H44=Forecast!$H$197,SUM(T44:BO44),IF(H44=Forecast!$H$198,AVERAGE(T44:BO44),0)))) -> 1.9999695 | T44: =INDEX(T41:T43,MATCH($D44,$D41:$D43,0))*IF(T6=1,1,$F44) -> 1 | U44: =INDEX(U41:U43,MATCH($D44,$D41:$D43,0))*IF(U6=1,1,$F44) -> 0 | V44: =INDEX(V41:V43,MATCH($D44,$D41:$D43,0))*IF(V6=1,1,$F44) -> 0 | W44: =INDEX(W41:W43,MATCH($D44,$D41:$D43,0))*IF(W6=1,1,$F44) -> 0.5 | X44: =INDEX(X41:X43,MATCH($D44,$D41:$D43,0))*IF(X6=1,1,$F44) -> 0 | Y44: =INDEX(Y41:Y43,MATCH($D44,$D41:$D43,0))*IF(Y6=1,1,$F44) -> 0 | Z44: =INDEX(Z41:Z43,MATCH($D44,$D41:$D43,0))*IF(Z6=1,1,$F44) -> 0.25 | AA44: =INDEX(AA41:AA43,MATCH($D44,$D41:$D43,0))*IF(AA6=1,1,$F44) -> 0 | ... BO44: =INDEX(BO41:BO43,MATCH($D44,$D41:$D43,0))*IF(BO6=1,1,$F44) -> 0
B45: Orders per 1 Existing Customer | C45: # | D45: estimated from the new cohort used above. this is manual, please change the formula here to fit what you want to estimate from the customers that were booked as new customers prior to the start of the model | H45: sum | I45: =IF(H45=Forecast!$H$195,T45,IF(H45=Forecast!$H$196,BO45,IF(H45=Forecast!$H$197,SUM(T45:BO45),IF(H45=Forecast!$H$198,AVERAGE(T45:BO45),0)))) -> 0.97915173 | T45: =$I44/48*(48-T6)/48 -> 0.040797989 | U45: =$I44/48*(48-U6)/48 -> 0.039929946 | V45: =$I44/48*(48-V6)/48 -> 0.039061904 | W45: =$I44/48*(48-W6)/48 -> 0.038193862 | X45: =$I44/48*(48-X6)/48 -> 0.037325819 | Y45: =$I44/48*(48-Y6)/48 -> 0.036457777 | Z45: =$I44/48*(48-Z6)/48 -> 0.035589735 | AA45: =$I44/48*(48-AA6)/48 -> 0.034721692 | ... BO45: =$I44/48*(48-BO6)/48 -> 0
...

Sheet Unit Economics
B2: Unit Economics
B3: Mauli transaction illustration; linked Foresight assumptions are not validated client economics.
B5: Per unit economics | D5: Amount | E5: Type, Notes
B7: Optional: Hide or show the column notes | D7: hide
B9: Revenues
B10: Recurring revenue (unused) | C10: ='Get Started'!D7 -> £ | D10: 0 | E10: Recurring
B11: One-time fee (unused) | C11: =C$10 -> £ | D11: 0 | E11: One time
B12: Order revenue incl. shipping | C12: =C$10 -> £ | D12: ='Get Started'!D17+'Get Started'!D28 -> 87 | E12: Transaction
B14: Cost of Sales
B15: Recurring costs (unused) | C15: % | D15: 0 | E15: Recurring
B16: One-time costs (unused) | C16: % | D16: 0 | E16: One time
B17: Order costs incl. shipping | C17: % | D17: =IF(D12=0,0,('Get Started'!D17*SUM('Get Started'!D22:D24)+'Get Started'!D29)/D12) -> 0.35 | E17: Transaction
B19: Optional: Discounts | E19: =IF(D7="hide","","optional, used in case you offer discounts for first subscription or first purchase")
B20: Discounts for recurring | C20: =C$10 -> £ | D20: 0 | E20: =IF(D7="hide","","total, over billing period")
B21: Discounts for transaction | C21: =C$10 -> £ | D21: 0 | E21: =IF(D7="hide","","total, first transaction only")
B23: Churn and Growth, Recurring
B24: Recurring - Period for billing, # of months | C24: # | D24: 3 | E24: =IF(D7="hide","","defines the billing cycle, so that cash collection can be separate from revenues. By default this equals the period for churn, but you can overwrite and change it")
B25: Recurring - Period for churn, growth, # months | C25: # | D25: 12 | E25: =IF(D7="hide","","define the length of a cycle for churn. Annual = 12, monthly = 1")
B26: ="% Growth in Gross Margin per unit, linear annual growth" -> % Growth in Gross Margin per unit, linear annual growth | C26: % | D26: 0 | E26: =IF(D7="hide","","annual rate, linear growth")
B27: ="% Churn, every "&MAX(1,D$25)&" month"&IF(D$25>1,"s","") -> % Churn, every 12 months | C27: % | D27: 0.1 | E27: =IF(D7="hide","","% that do not renew")
B28: Average Customer Lifetime | C28: # | D28: =IFERROR(1/(D27/MAX(1,D25)),0) -> 120 | E28: =IF(D7="hide","","# months")
B30: Timing, One time
B31: Months after acquisition when one-time occurs | C31: # | D31: 0 | E31: =IF(D7="hide","","month"&IF(D31>1,"s","")&"; this will be zero for upfront, one-time fees, perhaps assume 12 for one-time fees that happen after 1 year")
B33: Churn and Growth, Transaction
B34: Transaction - Period for churn, growth, # months | C34: # | D34: ='Get Started'!D44 -> 3 | E34: =IF(D7="hide","","month"&IF(D34>1,"s",""))
B35: ="% Growth in Gross Margin per unit, linear annual growth" -> % Growth in Gross Margin per unit, linear annual growth | C35: % | D35: 0 | E35: =IF(D7="hide","","annual rate, linear growth")
B36: ="% Churn, every period" -> % Churn, every period | C36: % | D36: ='Get Started'!D43 -> 0.5 | E36: =IF(D7="hide","","% that do not repeat")
B37: Average # Repeat Transactions per year | C37: # | D37: =IFERROR(12/D34,0) -> 4 | E37: =IF(D7="hide","","average lifetime one time purchases, before churn")
B38: Average # of Lifetime Transactions | C38: # | D38: =IFERROR(1/(D36/MAX(1,D34))/MAX(1,D34),0) -> 2 | E38: =IF(D7="hide","","calculated")
B40: Discount Rate | C40: % | D40: 0 | E40: =IF(D7="hide","","optional, assume an annual rate. used if you want to discount the future cash flows, using methodology from https://www.forentrepreneurs.com/ltv/ ")
B41: ="K, "&E60 -> K, Recurring | C41: # | D41: =IFERROR((1-D27/MAX(1,D25))*(1-D40),1) -> 0.99166667 | E41: =IF(D7="hide","","optional, only used if using discount rate")
B42: ="K, "&E62 -> K, Transaction | C42: # | D42: =IFERROR((1-D36/MAX(1,D34))*(1-D40),1) -> 0.83333333 | E42: =IF(D7="hide","","optional, only used if using discount rate")
B44: Acquisition and Retention Costs
B45: Customer Acquisition Cost (CAC) | C45: =C$10 -> £ | D45: ='Get Started'!D31 -> 30 | E45: =IF(D7="hide","","may need to adjust based on one time discounts, which costs to use from CAC forecast, and other business-specific issues")
B46: ="Cost of Retention and Expansion, "&E60 -> Cost of Retention and Expansion, Recurring | C46: =C$10 -> £ | D46: 0 | E46: =IF(D7="hide","","For subscription renewals")
B47: ="Cost of Repeat and Expansion, "&E62 -> Cost of Repeat and Expansion, Transaction | C47: =C$10 -> £ | D47: ='Get Started'!D32 -> 10 | E47: =IF(D7="hide","","For repeat transactions")
B49: ="LTV, "&E60 -> LTV, Recurring | C49: =C$10 -> £ | D49: =IFERROR(D69*(1/(1-D41)+D26*D41/(1-D41)^2)-D20,0) -> 0 | E49: =IF(D7="hide","",IF(D27=0,"LTV = "&AZ77&" months * gross margin per month, since no churn is assumed the model uses the max lifetime as used in the cash flow forecast","formula for LTV from https://www.forentrepreneurs.com/ltv/ to use discount rate (optional), and growth in average revenue (optional)"))
B50: ="LTV, "&E61 -> LTV, One time | C50: =C$10 -> £ | D50: =D67/(1+$D$40/12)^D31 -> 0 | E50: =IF(D7="hide","","LTV = revenues less cost of sales for this one time cash flow assumed in the first month of forecast")
B51: ="LTV, "&E62 -> LTV, Transaction | C51: =C$10 -> £ | D51: =IFERROR((D71*(1/(1-D42)+D35*D42/(1-D42)^2))/D34-D21,0) -> 93.1 | E51: =IF(D7="hide","",IF(D36=0,"LTV = "&AZ77&" months * gross margin per month, since no churn is assumed the model uses the max lifetime as used in the cash flow forecast","formula for LTV from https://www.forentrepreneurs.com/ltv/ to use discount rate (optional), and growth in average revenue (optional)"))
B52: LTV | C52: =C$10 -> £ | D52: =IF(SUM(D49,D51)=0,BA134,SUM(D49:D51)) -> 93.1 | E52: =IF(D7="hide","","sum of all LTVs")
...

Sheet Historicals
B2: Historical Performance by Cohort — template example
B4: Period | C4: Unit | D4: Note | S4: 0 | T4: =T6 -> 1 | U4: =U6 -> 2 | V4: =V6 -> 3 | W4: =W6 -> 4 | X4: =X6 -> 5 | Y4: =Y6 -> 6 | Z4: =Z6 -> 7 | AA4: =AA6 -> 8 | ... BO4: =BO6 -> 48
B5: Timestep | C5: # | D5: where the first month in the period = 0 | T5: 0 | U5: =T5+1 -> 1 | V5: =U5+1 -> 2 | W5: =V5+1 -> 3 | X5: =W5+1 -> 4 | Y5: =X5+1 -> 5 | Z5: =Y5+1 -> 6 | AA5: =Z5+1 -> 7 | AB5: =AA5+1 -> 8 | ... BO5: =BN5+1 -> 47
B6: Period # in Model | C6: # | D6: ="the model structure runs for "&BO6&" months. Month 0 is a pre-structure month, meant to capture opening items that help calculate the first month" -> the model structure runs for 48 months. Month 0 is a pre-structure month, meant to capture opening items that help calculate the first month | T6: 1 | U6: =T6+1 -> 2 | V6: =U6+1 -> 3 | W6: =V6+1 -> 4 | X6: =W6+1 -> 5 | Y6: =X6+1 -> 6 | Z6: =Y6+1 -> 7 | AA6: =Z6+1 -> 8 | AB6: =AA6+1 -> 9 | ... BO6: =BN6+1 -> 48
B7: Month | D7: month when cohort started, using dates from get started | T7: ='Get Started'!D12 -> 45596 | U7: =EDATE(T7,1) -> 45626 | V7: =EDATE(U7,1) -> 45656 | W7: =EDATE(V7,1) -> 45687 | X7: =EDATE(W7,1) -> 45716 | Y7: =EDATE(X7,1) -> 45744 | Z7: =EDATE(Y7,1) -> 45775 | AA7: =EDATE(Z7,1) -> 45805 | AB7: =EDATE(AA7,1) -> 45836 | ... BO7: =EDATE(BN7,1) -> 47024
B10: Orders | C10: # | D10: sum of the cohorts below | H10: sum | I10: =IF(H10=Forecast!$H$195,T10,IF(H10=Forecast!$H$196,BO10,IF(H10=Forecast!$H$197,SUM(T10:BO10),IF(H10=Forecast!$H$198,AVERAGE(T10:BO10),0)))) -> 109859.81 | S10: =SUM(S11:S59) -> 28904.417 | T10: =SUM(T11:T59) -> 28904.417 | U10: =SUM(U11:U59) -> 20170.534 | V10: =SUM(V11:V59) -> 16002.827 | W10: =SUM(W11:W59) -> 11878.102 | X10: =SUM(X11:X59) -> 8800.1196 | Y10: =SUM(Y11:Y59) -> 6506.3009 | Z10: =SUM(Z11:Z59) -> 4799.3567 | ... BO10: =SUM(BO11:BO59) -> 0
B11: =B10&" from Existing Customers" -> Orders from Existing Customers | C11: # | D11: 0 | H11: sum | I11: =IF(H11=Forecast!$H$195,T11,IF(H11=Forecast!$H$196,BO11,IF(H11=Forecast!$H$197,SUM(T11:BO11),IF(H11=Forecast!$H$198,AVERAGE(T11:BO11),0)))) -> 0 | S11: =T11 -> 0 | T11: 0 | U11: 0 | V11: 0 | W11: 0 | X11: 0 | Y11: 0 | Z11: 0 | AA11: 0 | AB11: 0 | AC11: 0 | AD11: 0 | AE11: 0 | AF11: 0 | AG11: 0 | AH11: 0 | AI11: 0 | AJ11: 0 | AK11: 0 | AL11: 0 | AM11: 0 | AN11: 0 | AO11: 0 | AP11: 0 | AQ11: 0 | AR11: 0 | AS11: 0 | AT11: 0 | AU11: 0 | AV11: 0 | AW11: 0 | AX11: 0 | AY11: 0 | AZ11: 0 | BA11: 0 | BB11: 0 | BC11: 0 | BD11: 0 | BE11: 0 | BF11: 0 | BG11: 0 | BH11: 0 | BI11: 0 | BJ11: 0 | BK11: 0 | BL11: 0 | BM11: 0 | BN11: 0 | BO11: 0
B12: =INDEX(T$7:BO$7,,D12) -> 45596 | C12: # | D12: 1 | H12: sum | I12: =IF(H12=Forecast!$H$195,T12,IF(H12=Forecast!$H$196,BO12,IF(H12=Forecast!$H$197,SUM(T12:BO12),IF(H12=Forecast!$H$198,AVERAGE(T12:BO12),0)))) -> 0 | S12: =T12 -> 0 | T12: 0 | U12: 0 | V12: 0 | W12: 0 | X12: 0 | Y12: 0 | Z12: 0 | AA12: 0 | AB12: 0 | AC12: 0 | AD12: 0 | AE12: 0 | AF12: 0 | AG12: 0 | AH12: 0 | AI12: 0 | AJ12: 0 | AK12: 0 | AL12: 0 | AM12: 0 | AN12: 0 | AO12: 0 | AP12: 0 | AQ12: 0 | AR12: 0 | AS12: 0 | AT12: 0 | AU12: 0 | AV12: 0 | AW12: 0 | AX12: 0 | AY12: 0 | AZ12: 0 | BA12: 0 | BB12: 0 | BC12: 0 | BD12: 0 | BE12: 0 | BF12: 0 | BG12: 0 | BH12: 0 | BI12: 0 | BJ12: 0 | BK12: 0 | BL12: 0 | BM12: 0 | BN12: 0 | BO12: 0
B13: =INDEX(T$7:BO$7,,D13) -> 45626 | C13: # | D13: =D12+1 -> 2 | H13: sum | I13: =IF(H13=Forecast!$H$195,T13,IF(H13=Forecast!$H$196,BO13,IF(H13=Forecast!$H$197,SUM(T13:BO13),IF(H13=Forecast!$H$198,AVERAGE(T13:BO13),0)))) -> 0 | S13: =T13 -> 0 | T13: 0 | U13: 0 | V13: 0 | W13: 0 | X13: 0 | Y13: 0 | Z13: 0 | AA13: 0 | AB13: 0 | AC13: 0 | AD13: 0 | AE13: 0 | AF13: 0 | AG13: 0 | AH13: 0 | AI13: 0 | AJ13: 0 | AK13: 0 | AL13: 0 | AM13: 0 | AN13: 0 | AO13: 0 | AP13: 0 | AQ13: 0 | AR13: 0 | AS13: 0 | AT13: 0 | AU13: 0 | AV13: 0 | AW13: 0 | AX13: 0 | AY13: 0 | AZ13: 0 | BA13: 0 | BB13: 0 | BC13: 0 | BD13: 0 | BE13: 0 | BF13: 0 | BG13: 0 | BH13: 0 | BI13: 0 | BJ13: 0 | BK13: 0 | BL13: 0 | BM13: 0 | BN13: 0 | BO13: 0
B14: =INDEX(T$7:BO$7,,D14) -> 45656 | C14: # | D14: =D13+1 -> 3 | H14: sum | I14: =IF(H14=Forecast!$H$195,T14,IF(H14=Forecast!$H$196,BO14,IF(H14=Forecast!$H$197,SUM(T14:BO14),IF(H14=Forecast!$H$198,AVERAGE(T14:BO14),0)))) -> 0 | S14: =T14 -> 0 | T14: 0 | U14: 0 | V14: 0 | W14: 0 | X14: 0 | Y14: 0 | Z14: 0 | AA14: 0 | AB14: 0 | AC14: 0 | AD14: 0 | AE14: 0 | AF14: 0 | AG14: 0 | AH14: 0 | AI14: 0 | AJ14: 0 | AK14: 0 | AL14: 0 | AM14: 0 | AN14: 0 | AO14: 0 | AP14: 0 | AQ14: 0 | AR14: 0 | AS14: 0 | AT14: 0 | AU14: 0 | AV14: 0 | AW14: 0 | AX14: 0 | AY14: 0 | AZ14: 0 | BA14: 0 | BB14: 0 | BC14: 0 | BD14: 0 | BE14: 0 | BF14: 0 | BG14: 0 | BH14: 0 | BI14: 0 | BJ14: 0 | BK14: 0 | BL14: 0 | BM14: 0 | BN14: 0 | BO14: 0
B15: =INDEX(T$7:BO$7,,D15) -> 45687 | C15: # | D15: =D14+1 -> 4 | H15: sum | I15: =IF(H15=Forecast!$H$195,T15,IF(H15=Forecast!$H$196,BO15,IF(H15=Forecast!$H$197,SUM(T15:BO15),IF(H15=Forecast!$H$198,AVERAGE(T15:BO15),0)))) -> 0 | S15: =T15 -> 0 | T15: 0 | U15: 0 | V15: 0 | W15: 0 | X15: 0 | Y15: 0 | Z15: 0 | AA15: 0 | AB15: 0 | AC15: 0 | AD15: 0 | AE15: 0 | AF15: 0 | AG15: 0 | AH15: 0 | AI15: 0 | AJ15: 0 | AK15: 0 | AL15: 0 | AM15: 0 | AN15: 0 | AO15: 0 | AP15: 0 | AQ15: 0 | AR15: 0 | AS15: 0 | AT15: 0 | AU15: 0 | AV15: 0 | AW15: 0 | AX15: 0 | AY15: 0 | AZ15: 0 | BA15: 0 | BB15: 0 | BC15: 0 | BD15: 0 | BE15: 0 | BF15: 0 | BG15: 0 | BH15: 0 | BI15: 0 | BJ15: 0 | BK15: 0 | BL15: 0 | BM15: 0 | BN15: 0 | BO15: 0
B16: =INDEX(T$7:BO$7,,D16) -> 45716 | C16: # | D16: =D15+1 -> 5 | H16: sum | I16: =IF(H16=Forecast!$H$195,T16,IF(H16=Forecast!$H$196,BO16,IF(H16=Forecast!$H$197,SUM(T16:BO16),IF(H16=Forecast!$H$198,AVERAGE(T16:BO16),0)))) -> 0 | S16: =T16 -> 0 | T16: 0 | U16: 0 | V16: 0 | W16: 0 | X16: 0 | Y16: 0 | Z16: 0 | AA16: 0 | AB16: 0 | AC16: 0 | AD16: 0 | AE16: 0 | AF16: 0 | AG16: 0 | AH16: 0 | AI16: 0 | AJ16: 0 | AK16: 0 | AL16: 0 | AM16: 0 | AN16: 0 | AO16: 0 | AP16: 0 | AQ16: 0 | AR16: 0 | AS16: 0 | AT16: 0 | AU16: 0 | AV16: 0 | AW16: 0 | AX16: 0 | AY16: 0 | AZ16: 0 | BA16: 0 | BB16: 0 | BC16: 0 | BD16: 0 | BE16: 0 | BF16: 0 | BG16: 0 | BH16: 0 | BI16: 0 | BJ16: 0 | BK16: 0 | BL16: 0 | BM16: 0 | BN16: 0 | BO16: 0
B17: =INDEX(T$7:BO$7,,D17) -> 45744 | C17: # | D17: =D16+1 -> 6 | H17: sum | I17: =IF(H17=Forecast!$H$195,T17,IF(H17=Forecast!$H$196,BO17,IF(H17=Forecast!$H$197,SUM(T17:BO17),IF(H17=Forecast!$H$198,AVERAGE(T17:BO17),0)))) -> 0 | S17: =T17 -> 0 | T17: 0 | U17: 0 | V17: 0 | W17: 0 | X17: 0 | Y17: 0 | Z17: 0 | AA17: 0 | AB17: 0 | AC17: 0 | AD17: 0 | AE17: 0 | AF17: 0 | AG17: 0 | AH17: 0 | AI17: 0 | AJ17: 0 | AK17: 0 | AL17: 0 | AM17: 0 | AN17: 0 | AO17: 0 | AP17: 0 | AQ17: 0 | AR17: 0 | AS17: 0 | AT17: 0 | AU17: 0 | AV17: 0 | AW17: 0 | AX17: 0 | AY17: 0 | AZ17: 0 | BA17: 0 | BB17: 0 | BC17: 0 | BD17: 0 | BE17: 0 | BF17: 0 | BG17: 0 | BH17: 0 | BI17: 0 | BJ17: 0 | BK17: 0 | BL17: 0 | BM17: 0 | BN17: 0 | BO17: 0
B18: =INDEX(T$7:BO$7,,D18) -> 45775 | C18: # | D18: =D17+1 -> 7 | H18: sum | I18: =IF(H18=Forecast!$H$195,T18,IF(H18=Forecast!$H$196,BO18,IF(H18=Forecast!$H$197,SUM(T18:BO18),IF(H18=Forecast!$H$198,AVERAGE(T18:BO18),0)))) -> 0 | S18: =T18 -> 0 | T18: 0 | U18: 0 | V18: 0 | W18: 0 | X18: 0 | Y18: 0 | Z18: 0 | AA18: 0 | AB18: 0 | AC18: 0 | AD18: 0 | AE18: 0 | AF18: 0 | AG18: 0 | AH18: 0 | AI18: 0 | AJ18: 0 | AK18: 0 | AL18: 0 | AM18: 0 | AN18: 0 | AO18: 0 | AP18: 0 | AQ18: 0 | AR18: 0 | AS18: 0 | AT18: 0 | AU18: 0 | AV18: 0 | AW18: 0 | AX18: 0 | AY18: 0 | AZ18: 0 | BA18: 0 | BB18: 0 | BC18: 0 | BD18: 0 | BE18: 0 | BF18: 0 | BG18: 0 | BH18: 0 | BI18: 0 | BJ18: 0 | BK18: 0 | BL18: 0 | BM18: 0 | BN18: 0 | BO18: 0
B19: =INDEX(T$7:BO$7,,D19) -> 45805 | C19: # | D19: =D18+1 -> 8 | H19: sum | I19: =IF(H19=Forecast!$H$195,T19,IF(H19=Forecast!$H$196,BO19,IF(H19=Forecast!$H$197,SUM(T19:BO19),IF(H19=Forecast!$H$198,AVERAGE(T19:BO19),0)))) -> 0 | S19: =T19 -> 0 | T19: 0 | U19: 0 | V19: 0 | W19: 0 | X19: 0 | Y19: 0 | Z19: 0 | AA19: 0 | AB19: 0 | AC19: 0 | AD19: 0 | AE19: 0 | AF19: 0 | AG19: 0 | AH19: 0 | AI19: 0 | AJ19: 0 | AK19: 0 | AL19: 0 | AM19: 0 | AN19: 0 | AO19: 0 | AP19: 0 | AQ19: 0 | AR19: 0 | AS19: 0 | AT19: 0 | AU19: 0 | AV19: 0 | AW19: 0 | AX19: 0 | AY19: 0 | AZ19: 0 | BA19: 0 | BB19: 0 | BC19: 0 | BD19: 0 | BE19: 0 | BF19: 0 | BG19: 0 | BH19: 0 | BI19: 0 | BJ19: 0 | BK19: 0 | BL19: 0 | BM19: 0 | BN19: 0 | BO19: 0
B20: =INDEX(T$7:BO$7,,D20) -> 45836 | C20: # | D20: =D19+1 -> 9 | H20: sum | I20: =IF(H20=Forecast!$H$195,T20,IF(H20=Forecast!$H$196,BO20,IF(H20=Forecast!$H$197,SUM(T20:BO20),IF(H20=Forecast!$H$198,AVERAGE(T20:BO20),0)))) -> 0 | S20: =T20 -> 0 | T20: 0 | U20: 0 | V20: 0 | W20: 0 | X20: 0 | Y20: 0 | Z20: 0 | AA20: 0 | AB20: 0 | AC20: 0 | AD20: 0 | AE20: 0 | AF20: 0 | AG20: 0 | AH20: 0 | AI20: 0 | AJ20: 0 | AK20: 0 | AL20: 0 | AM20: 0 | AN20: 0 | AO20: 0 | AP20: 0 | AQ20: 0 | AR20: 0 | AS20: 0 | AT20: 0 | AU20: 0 | AV20: 0 | AW20: 0 | AX20: 0 | AY20: 0 | AZ20: 0 | BA20: 0 | BB20: 0 | BC20: 0 | BD20: 0 | BE20: 0 | BF20: 0 | BG20: 0 | BH20: 0 | BI20: 0 | BJ20: 0 | BK20: 0 | BL20: 0 | BM20: 0 | BN20: 0 | BO20: 0
B21: =INDEX(T$7:BO$7,,D21) -> 45866 | C21: # | D21: =D20+1 -> 10 | H21: sum | I21: =IF(H21=Forecast!$H$195,T21,IF(H21=Forecast!$H$196,BO21,IF(H21=Forecast!$H$197,SUM(T21:BO21),IF(H21=Forecast!$H$198,AVERAGE(T21:BO21),0)))) -> 0 | S21: =T21 -> 0 | T21: 0 | U21: 0 | V21: 0 | W21: 0 | X21: 0 | Y21: 0 | Z21: 0 | AA21: 0 | AB21: 0 | AC21: 0 | AD21: 0 | AE21: 0 | AF21: 0 | AG21: 0 | AH21: 0 | AI21: 0 | AJ21: 0 | AK21: 0 | AL21: 0 | AM21: 0 | AN21: 0 | AO21: 0 | AP21: 0 | AQ21: 0 | AR21: 0 | AS21: 0 | AT21: 0 | AU21: 0 | AV21: 0 | AW21: 0 | AX21: 0 | AY21: 0 | AZ21: 0 | BA21: 0 | BB21: 0 | BC21: 0 | BD21: 0 | BE21: 0 | BF21: 0 | BG21: 0 | BH21: 0 | BI21: 0 | BJ21: 0 | BK21: 0 | BL21: 0 | BM21: 0 | BN21: 0 | BO21: 0
B22: =INDEX(T$7:BO$7,,D22) -> 45897 | C22: # | D22: =D21+1 -> 11 | H22: sum | I22: =IF(H22=Forecast!$H$195,T22,IF(H22=Forecast!$H$196,BO22,IF(H22=Forecast!$H$197,SUM(T22:BO22),IF(H22=Forecast!$H$198,AVERAGE(T22:BO22),0)))) -> 0 | S22: =T22 -> 0 | T22: 0 | U22: 0 | V22: 0 | W22: 0 | X22: 0 | Y22: 0 | Z22: 0 | AA22: 0 | AB22: 0 | AC22: 0 | AD22: 0 | AE22: 0 | AF22: 0 | AG22: 0 | AH22: 0 | AI22: 0 | AJ22: 0 | AK22: 0 | AL22: 0 | AM22: 0 | AN22: 0 | AO22: 0 | AP22: 0 | AQ22: 0 | AR22: 0 | AS22: 0 | AT22: 0 | AU22: 0 | AV22: 0 | AW22: 0 | AX22: 0 | AY22: 0 | AZ22: 0 | BA22: 0 | BB22: 0 | BC22: 0 | BD22: 0 | BE22: 0 | BF22: 0 | BG22: 0 | BH22: 0 | BI22: 0 | BJ22: 0 | BK22: 0 | BL22: 0 | BM22: 0 | BN22: 0 | BO22: 0
B23: =INDEX(T$7:BO$7,,D23) -> 45928 | C23: # | D23: =D22+1 -> 12 | H23: sum | I23: =IF(H23=Forecast!$H$195,T23,IF(H23=Forecast!$H$196,BO23,IF(H23=Forecast!$H$197,SUM(T23:BO23),IF(H23=Forecast!$H$198,AVERAGE(T23:BO23),0)))) -> 0 | S23: =T23 -> 0 | T23: 0 | U23: 0 | V23: 0 | W23: 0 | X23: 0 | Y23: 0 | Z23: 0 | AA23: 0 | AB23: 0 | AC23: 0 | AD23: 0 | AE23: 0 | AF23: 0 | AG23: 0 | AH23: 0 | AI23: 0 | AJ23: 0 | AK23: 0 | AL23: 0 | AM23: 0 | AN23: 0 | AO23: 0 | AP23: 0 | AQ23: 0 | AR23: 0 | AS23: 0 | AT23: 0 | AU23: 0 | AV23: 0 | AW23: 0 | AX23: 0 | AY23: 0 | AZ23: 0 | BA23: 0 | BB23: 0 | BC23: 0 | BD23: 0 | BE23: 0 | BF23: 0 | BG23: 0 | BH23: 0 | BI23: 0 | BJ23: 0 | BK23: 0 | BL23: 0 | BM23: 0 | BN23: 0 | BO23: 0
B24: =INDEX(T$7:BO$7,,D24) -> 45958 | C24: # | D24: =D23+1 -> 13 | H24: sum | I24: =IF(H24=Forecast!$H$195,T24,IF(H24=Forecast!$H$196,BO24,IF(H24=Forecast!$H$197,SUM(T24:BO24),IF(H24=Forecast!$H$198,AVERAGE(T24:BO24),0)))) -> 0 | S24: =T24 -> 0 | T24: 0 | U24: 0 | V24: 0 | W24: 0 | X24: 0 | Y24: 0 | Z24: 0 | AA24: 0 | AB24: 0 | AC24: 0 | AD24: 0 | AE24: 0 | AF24: 0 | AG24: 0 | AH24: 0 | AI24: 0 | AJ24: 0 | AK24: 0 | AL24: 0 | AM24: 0 | AN24: 0 | AO24: 0 | AP24: 0 | AQ24: 0 | AR24: 0 | AS24: 0 | AT24: 0 | AU24: 0 | AV24: 0 | AW24: 0 | AX24: 0 | AY24: 0 | AZ24: 0 | BA24: 0 | BB24: 0 | BC24: 0 | BD24: 0 | BE24: 0 | BF24: 0 | BG24: 0 | BH24: 0 | BI24: 0 | BJ24: 0 | BK24: 0 | BL24: 0 | BM24: 0 | BN24: 0 | BO24: 0
... B34: =INDEX(T$7:BO$7,,D34) -> 46262 | C34: # | D34: =D33+1 -> 23 | H34: sum | I34: =IF(H34=Forecast!$H$195,T34,IF(H34=Forecast!$H$196,BO34,IF(H34=Forecast!$H$197,SUM(T34:BO34),IF(H34=Forecast!$H$198,AVERAGE(T34:BO34),0)))) -> 0 | S34: =T34 -> 0 | T34: 0 | U34: 0 | V34: 0 | W34: 0 | X34: 0 | Y34: 0 | Z34: 0 | AA34: 0 | AB34: 0 | AC34: 0 | AD34: 0 | AE34: 0 | AF34: 0 | AG34: 0 | AH34: 0 | AI34: 0 | AJ34: 0 | AK34: 0 | AL34: 0 | AM34: 0 | AN34: 0 | AO34: 0 | AP34: 0 | AQ34: 0 | AR34: 0 | AS34: 0 | AT34: 0 | AU34: 0 | AV34: 0 | AW34: 0 | AX34: 0 | AY34: 0 | AZ34: 0 | BA34: 0 | BB34: 0 | BC34: 0 | BD34: 0 | BE34: 0 | BF34: 0 | BG34: 0 | BH34: 0 | BI34: 0 | BJ34: 0 | BK34: 0 | BL34: 0 | BM34: 0 | BN34: 0 | BO34: 0
